Workbook

Sheet SegmentA

Sheet SegmentB
A1: year | B1: campany | C1: type | D1: length | E1: width | F1: weightLow | G1: weightUp | H1: MeanWeight | I1: MeanWeight Segement B
A2: 1975 | B2: VW | C2: Polo I | D2: 3512 | E2: 1560 | F2: 685 | G2: 700 | H2: =AVERAGE(F2:G2) -> 692.5 | I2: =AVERAGE(H2,H55) -> 741.25
A3: 1976 | B3: VW | C3: Polo I | D3: 3512 | E3: 1560 | F3: 685 | G3: 700 | H3: =AVERAGE(F3:G3) -> 692.5 | I3: =AVERAGE(H3,H56) -> 741.25
A4: 1977 | B4: VW | C4: Polo I | D4: 3512 | E4: 1560 | F4: 685 | G4: 700 | H4: =AVERAGE(F4:G4) -> 692.5 | I4: =AVERAGE(H4,H57) -> 741.25
A5: 1978 | B5: VW | C5: Polo I | D5: 3512 | E5: 1560 | F5: 685 | G5: 700 | H5: =AVERAGE(F5:G5) -> 692.5 | I5: =AVERAGE(H5,H58) -> 741.25
A6: 1979 | B6: VW | C6: Polo I | D6: 3512 | E6: 1560 | F6: 685 | G6: 700 | H6: =AVERAGE(F6:G6) -> 692.5 | I6: =AVERAGE(H6,H59) -> 741.25
A7: 1980 | B7: VW | C7: Polo I | D7: 3512 | E7: 1560 | F7: 685 | G7: 700 | H7: =AVERAGE(F7:G7) -> 692.5 | I7: =AVERAGE(H7,H60) -> 741.25
A8: 1981 | B8: VW | C8: Polo I/II | D8: 3655 | E8: 1580 | F8: 725 | G8: 830 | H8: =AVERAGE(F8:G8) -> 777.5 | I8: =AVERAGE(H8,H61) -> 783.75
A9: 1982 | B9: VW | C9: Polo II | D9: 3655 | E9: 1580 | F9: 725 | G9: 830 | H9: =AVERAGE(F9:G9) -> 777.5 | I9: =AVERAGE(H9,H62) -> 783.75
A10: 1983 | B10: VW | C10: Polo II | D10: 3655 | E10: 1580 | F10: 725 | G10: 830 | H10: =AVERAGE(F10:G10) -> 777.5 | I10: =AVERAGE(H10,H63) -> 788.75
A11: 1984 | B11: VW | C11: Polo II | D11: 3655 | E11: 1580 | F11: 725 | G11: 830 | H11: =AVERAGE(F11:G11) -> 777.5 | I11: =AVERAGE(H11,H64) -> 788.75
A12: 1985 | B12: VW | C12: Polo II | D12: 3655 | E12: 1580 | F12: 725 | G12: 830 | H12: =AVERAGE(F12:G12) -> 777.5 | I12: =AVERAGE(H12,H65) -> 788.75
A13: 1986 | B13: VW | C13: Polo II | D13: 3655 | E13: 1580 | F13: 725 | G13: 830 | H13: =AVERAGE(F13:G13) -> 777.5 | I13: =AVERAGE(H13,H66) -> 788.75
... A35: 2008 | B35: VW | C35: Polo IV | D35: 3897 | E35: 1650 | F35: 980 | G35: 1155 | H35: =AVERAGE(F35:G35) -> 1067.5 | I35: =AVERAGE(H35,H88) -> 1185.75
A36: 2009 | B36: VW | C36: Polo IV/V | D36: 3970-3983 | E36: 1682 | F36: 1050 | G36: 1269 | H36: =AVERAGE(F36:G36) -> 1159.5 | I36: =AVERAGE(H36,H89) -> 1231.75
A37: 2010 | B37: VW | C37: Polo V | D37: 3970-3983 | E37: 1682 | F37: 1050 | G37: 1269 | H37: =AVERAGE(F37:G37) -> 1159.5 | I37: =AVERAGE(H37,H90) -> 1231.75
A38: 2011 | B38: VW | C38: Polo V | D38: 3970-3983 | E38: 1682 | F38: 1050 | G38: 1269 | H38: =AVERAGE(F38:G38) -> 1159.5 | I38: =AVERAGE(H38,H91) -> 1231.75
A39: 2012 | B39: VW | C39: Polo V | D39: 3970-3983 | E39: 1682 | F39: 1050 | G39: 1269 | H39: =AVERAGE(F39:G39) -> 1159.5 | I39: =AVERAGE(H39,H92) -> 1178
A40: 2013 | B40: VW | C40: Polo V | D40: 3970-3983 | E40: 1682 | F40: 1050 | G40: 1269 | H40: =AVERAGE(F40:G40) -> 1159.5 | I40: =AVERAGE(H40,H93) -> 1178
A41: 2014 | B41: VW | C41: Polo V | D41: 3970-3983 | E41: 1682 | F41: 1050 | G41: 1269 | H41: =AVERAGE(F41:G41) -> 1159.5 | I41: =AVERAGE(H41,H94) -> 1178
A42: 2015 | B42: VW | C42: Polo V | D42: 3970-3983 | E42: 1682 | F42: 1050 | G42: 1269 | H42: =AVERAGE(F42:G42) -> 1159.5 | I42: =AVERAGE(H42,H95) -> 1178
A43: 2016 | B43: VW | C43: Polo V | D43: 3970-3983 | E43: 1682 | F43: 1050 | G43: 1269 | H43: =AVERAGE(F43:G43) -> 1159.5 | I43: =AVERAGE(H43,H96) -> 1178
A44: 2017 | B44: VW | C44: Polo V/VI | D44: 4053 | E44: 1461 | F44: 1105 | G44: 1355 | H44: =AVERAGE(F44:G44) -> 1230 | I44: =AVERAGE(H44,H97) -> 1213.25
A45: 2018 | B45: VW | C45: Polo VI | D45: 4053 | E45: 1461 | F45: 1105 | G45: 1355 | H45: =AVERAGE(F45:G45) -> 1230 | I45: =AVERAGE(H45,H98) -> 1213.25
A46: 2019 | B46: VW | C46: Polo VI | D46: 4053 | E46: 1461 | F46: 1105 | G46: 1355 | H46: =AVERAGE(F46:G46) -> 1230 | I46: =AVERAGE(H46,H99) -> 1275
A47: 2020 | B47: VW | C47: Polo VI | D47: 4053 | E47: 1461 | F47: 1105 | G47: 1355 | H47: =AVERAGE(F47:G47) -> 1230 | I47: =AVERAGE(H47,H100) -> 1275
A48: 2021 | B48: VW | C48: Polo VI | D48: 4053 | E48: 1461 | F48: 1105 | G48: 1355 | H48: =AVERAGE(F48:G48) -> 1230 | I48: =AVERAGE(H48,H101) -> 1275
A49: 2022 | B49: VW | C49: Polo VI | D49: 4053 | E49: 1461 | F49: 1105 | G49: 1355 | H49: =AVERAGE(F49:G49) -> 1230 | I49: =AVERAGE(H49,H102) -> 1275
A50: 2023 | B50: VW | C50: Polo VI | D50: 4053 | E50: 1461 | F50: 1105 | G50: 1355 | H50: =AVERAGE(F50:G50) -> 1230 | I50: =AVERAGE(H50,H103) -> 1275
A51: 2024 | B51: VW | C51: Polo VI | D51: 4053 | E51: 1461 | F51: 1105 | G51: 1355 | H51: =AVERAGE(F51:G51) -> 1230 | I51: =AVERAGE(H51,H104) -> 1275
A52: 1972 | B52: Peugeot | C52: 104 | D52: 3283-3600 | E52: 1520 | F52: 760 | G52: 820 | H52: =AVERAGE(F52:G52) -> 790
A53: 1973 | B53: Peugeot | C53: 104 | D53: 3283-3600 | E53: 1520 | F53: 760 | G53: 820 | H53: =AVERAGE(F53:G53) -> 790
A54: 1974 | B54: Peugeot | C54: 104 | D54: 3283-3600 | E54: 1520 | F54: 760 | G54: 820 | H54: =AVERAGE(F54:G54) -> 790
A55: 1975 | B55: Peugeot | C55: 104 | D55: 3283-3600 | E55: 1520 | F55: 760 | G55: 820 | H55: =AVERAGE(F55:G55) -> 790
A56: 1976 | B56: Peugeot | C56: 104 | D56: 3283-3600 | E56: 1520 | F56: 760 | G56: 820 | H56: =AVERAGE(F56:G56) -> 790
A57: 1977 | B57: Peugeot | C57: 104 | D57: 3283-3600 | E57: 1520 | F57: 760 | G57: 820 | H57: =AVERAGE(F57:G57) -> 790
A58: 1978 | B58: Peugeot | C58: 104 | D58: 3283-3600 | E58: 1520 | F58: 760 | G58: 820 | H58: =AVERAGE(F58:G58) -> 790
A59: 1979 | B59: Peugeot | C59: 104 | D59: 3283-3600 | E59: 1520 | F59: 760 | G59: 820 | H59: =AVERAGE(F59:G59) -> 790
A60: 1980 | B60: Peugeot | C60: 104 | D60: 3283-3600 | E60: 1520 | F60: 760 | G60: 820 | H60: =AVERAGE(F60:G60) -> 790
A61: 1981 | B61: Peugeot | C61: 104 | D61: 3283-3600 | E61: 1520 | F61: 760 | G61: 820 | H61: =AVERAGE(F61:G61) -> 790
...

Sheet Segment C
A1: year | B1: campany | C1: type | D1: length | E1: width | F1: weightLow | G1: weightUp
A2: 1974 | B2: VW | C2: Golf I | D2: 3705 | E2: 1610 | F2: 750 | G2: 805 | H2: =AVERAGE(F2:G2) -> 777.5
A3: 1975 | B3: VW | C3: Golf I | D3: 3705 | E3: 1610 | F3: 750 | G3: 805 | H3: =AVERAGE(F3:G3) -> 777.5 | I3: =AVERAGE(H3,H53,H104) -> 868.33333
A4: 1976 | B4: VW | C4: Golf I | D4: 3705 | E4: 1610 | F4: 750 | G4: 805 | H4: =AVERAGE(F4:G4) -> 777.5 | I4: =AVERAGE(H4,H54,H105) -> 868.33333
A5: 1977 | B5: VW | C5: Golf I | D5: 3705 | E5: 1610 | F5: 750 | G5: 805 | H5: =AVERAGE(F5:G5) -> 777.5 | I5: =AVERAGE(H5,H55,H106) -> 868.33333
A6: 1978 | B6: VW | C6: Golf I | D6: 3705 | E6: 1610 | F6: 750 | G6: 805 | H6: =AVERAGE(F6:G6) -> 777.5 | I6: =AVERAGE(H6,H56,H107) -> 868.33333
A7: 1979 | B7: VW | C7: Golf I | D7: 3705 | E7: 1610 | F7: 750 | G7: 805 | H7: =AVERAGE(F7:G7) -> 777.5 | I7: =AVERAGE(H7,H57,H108) -> 868.33333
A8: 1980 | B8: VW | C8: Golf I | D8: 3705 | E8: 1610 | F8: 750 | G8: 805 | H8: =AVERAGE(F8:G8) -> 777.5 | I8: =AVERAGE(H8,H58,H109) -> 872.5
A9: 1981 | B9: VW | C9: Golf I | D9: 3705 | E9: 1610 | F9: 750 | G9: 805 | H9: =AVERAGE(F9:G9) -> 777.5 | I9: =AVERAGE(H9,H59,H110) -> 872.5
A10: 1982 | B10: VW | C10: Golf I | D10: 3705 | E10: 1610 | F10: 750 | G10: 805 | H10: =AVERAGE(F10:G10) -> 777.5 | I10: =AVERAGE(H10,H60,H111) -> 872.5
A11: 1983 | B11: VW | C11: Golf I/II | D11: 3985-4040 | E11: 1665-1680 | F11: 845 | G11: 1165 | H11: =AVERAGE(F11:G11) -> 1005 | I11: =AVERAGE(H11,H61,H112) -> 950.83333
A12: 1984 | B12: VW | C12: Golf II | D12: 3985-4040 | E12: 1665-1680 | F12: 845 | G12: 1165 | H12: =AVERAGE(F12:G12) -> 1005 | I12: =AVERAGE(H12,H62,H113) -> 950.83333
A13: 1985 | B13: VW | C13: Golf II | D13: 3985-4040 | E13: 1665-1680 | F13: 845 | G13: 1165 | H13: =AVERAGE(F13:G13) -> 1005 | I13: =AVERAGE(H13,H63,H114) -> 935.83333
A14: 1986 | B14: VW | C14: Golf II | D14: 3985-4040 | E14: 1665-1680 | F14: 845 | G14: 1165 | H14: =AVERAGE(F14:G14) -> 1005 | I14: =AVERAGE(H14,H64,H115) -> 935.83333
A15: 1987 | B15: VW | C15: Golf II | D15: 3985-4040 | E15: 1665-1680 | F15: 845 | G15: 1165 | H15: =AVERAGE(F15:G15) -> 1005 | I15: =AVERAGE(H15,H65,H116) -> 935.83333
A16: 1988 | B16: VW | C16: Golf II | D16: 3985-4040 | E16: 1665-1680 | F16: 845 | G16: 1165 | H16: =AVERAGE(F16:G16) -> 1005 | I16: =AVERAGE(H16,H66,H117) -> 985.83333
A17: 1989 | B17: VW | C17: Golf II | D17: 3985-4040 | E17: 1665-1680 | F17: 845 | G17: 1165 | H17: =AVERAGE(F17:G17) -> 1005 | I17: =AVERAGE(H17,H67,H118) -> 985.83333
A18: 1990 | B18: VW | C18: Golf II | D18: 3985-4040 | E18: 1665-1680 | F18: 845 | G18: 1165 | H18: =AVERAGE(F18:G18) -> 1005 | I18: =AVERAGE(H18,H68,H119) -> 985.83333
A19: 1991 | B19: VW | C19: Golf II/III | D19: 4020 | E19: 1695-1710 | F19: 960 | G19: 1380 | H19: =AVERAGE(F19:G19) -> 1170 | I19: =AVERAGE(H19,H69,H120) -> 1040.8333
A20: 1992 | B20: VW | C20: Golf II/III | D20: 4020 | E20: 1695-1710 | F20: 960 | G20: 1380 | H20: =AVERAGE(F20:G20) -> 1170 | I20: =AVERAGE(H20,H70,H121) -> 1040.8333
A21: 1993 | B21: VW | C21: Golf III | D21: 4020 | E21: 1695-1710 | F21: 960 | G21: 1380 | H21: =AVERAGE(F21:G21) -> 1170 | I21: =AVERAGE(H21,H71,H122) -> 1130.8333
A22: 1994 | B22: VW | C22: Golf III | D22: 4020 | E22: 1695-1710 | F22: 960 | G22: 1380 | H22: =AVERAGE(F22:G22) -> 1170 | I22: =AVERAGE(H22,H72,H123) -> 1130.8333
A23: 1995 | B23: VW | C23: Golf III | D23: 4020 | E23: 1695-1710 | F23: 960 | G23: 1380 | H23: =AVERAGE(F23:G23) -> 1170 | I23: =AVERAGE(H23,H73,H124) -> 1160
A24: 1996 | B24: VW | C24: Golf III | D24: 4020 | E24: 1695-1710 | F24: 960 | G24: 1380 | H24: =AVERAGE(F24:G24) -> 1170 | I24: =AVERAGE(H24,H74,H125) -> 1160
A25: 1997 | B25: VW | C25: Golf III/IV | D25: 4149-4397 | E25: 1735 | F25: 1050 | G25: 1477 | H25: =AVERAGE(F25:G25) -> 1263.5 | I25: =AVERAGE(H25,H75,H126) -> 1191.1667
A26: 1998 | B26: VW | C26: Golf IV | D26: 4149-4397 | E26: 1735 | F26: 1050 | G26: 1477 | H26: =AVERAGE(F26:G26) -> 1263.5 | I26: =AVERAGE(H26,H76,H127) -> 1191.1667
A27: 1999 | B27: VW | C27: Golf IV | D27: 4149-4397 | E27: 1735 | F27: 1050 | G27: 1477 | H27: =AVERAGE(F27:G27) -> 1263.5 | I27: =AVERAGE(H27,H77,H128) -> 1180.3333
A28: 2000 | B28: VW | C28: Golf IV | D28: 4149-4397 | E28: 1735 | F28: 1050 | G28: 1477 | H28: =AVERAGE(F28:G28) -> 1263.5 | I28: =AVERAGE(H28,H78,H129) -> 1180.3333
A29: 2001 | B29: VW | C29: Golf IV | D29: 4149-4397 | E29: 1735 | F29: 1050 | G29: 1477 | H29: =AVERAGE(F29:G29) -> 1263.5 | I29: =AVERAGE(H29,H79,H130) -> 1304.8333
A30: 2002 | B30: VW | C30: Golf IV | D30: 4149-4397 | E30: 1735 | F30: 1050 | G30: 1477 | H30: =AVERAGE(F30:G30) -> 1263.5 | I30: =AVERAGE(H30,H80,H131) -> 1304.8333
A31: 2003 | B31: VW | C31: Golf IV/V | D31: 4204-4206 | E31: 1759 | F31: 1155 | G31: 1590 | H31: =AVERAGE(F31:G31) -> 1372.5 | I31: =AVERAGE(H31,H81,H132) -> 1341.1667
A32: 2004 | B32: VW | C32: Golf V | D32: 4204-4206 | E32: 1759 | F32: 1155 | G32: 1590 | H32: =AVERAGE(F32:G32) -> 1372.5 | I32: =AVERAGE(H32,H82,H133) -> 1341.1667
A33: 2005 | B33: VW | C33: Golf V | D33: 4204-4206 | E33: 1759 | F33: 1155 | G33: 1590 | H33: =AVERAGE(F33:G33) -> 1372.5 | I33: =AVERAGE(H33,H83,H134) -> 1341.1667
A34: 2006 | B34: VW | C34: Golf V | D34: 4204-4206 | E34: 1759 | F34: 1155 | G34: 1590 | H34: =AVERAGE(F34:G34) -> 1372.5 | I34: =AVERAGE(H34,H84,H135) -> 1341.1667
A35: 2007 | B35: VW | C35: Golf V | D35: 4204-4206 | E35: 1759 | F35: 1155 | G35: 1590 | H35: =AVERAGE(F35:G35) -> 1372.5 | I35: =AVERAGE(H35,H85,H136) -> 1392.8333
A36: 2008 | B36: VW | C36: Golf V/VI | D36: 4199-4534 | E36: 1779-1786 | F36: 1271 | G36: 1541 | H36: =AVERAGE(F36:G36) -> 1406 | I36: =AVERAGE(H36,H86,H137) -> 1404
A37: 2009 | B37: VW | C37: Golf VI | D37: 4199-4534 | E37: 1779-1786 | F37: 1271 | G37: 1541 | H37: =AVERAGE(F37:G37) -> 1406 | I37: =AVERAGE(H37,H87,H138) -> 1404
A38: 2010 | B38: VW | C38: Golf VI | D38: 4199-4534 | E38: 1779-1786 | F38: 1271 | G38: 1541 | H38: =AVERAGE(F38:G38) -> 1406 | I38: =AVERAGE(H38,H88,H139) -> 1404
A39: 2011 | B39: VW | C39: Golf VI | D39: 4199-4534 | E39: 1779-1786 | F39: 1271 | G39: 1541 | H39: =AVERAGE(F39:G39) -> 1406 | I39: =AVERAGE(H39,H89,H140) -> 1404
A40: 2012 | B40: VW | C40: Golf VI/VII | D40: 4255-4586 | E40: 1779-1786 | F40: 1205 | G40: 1615 | H40: =AVERAGE(F40:G40) -> 1410 | I40: =AVERAGE(H40,H90,H141) -> 1405.3333
...

Sheet SegmentD
A1: year | B1: campany | C1: type | D1: length | E1: width | F1: weightLow | G1: weightUp | H1: Mein Weight | I1: Mein Weight Segment D
A2: 1973 | B2: VW | C2: Passat B1 | D2: 4200 | E2: 1620 | F2: 880 | G2: 995 | H2: =AVERAGE(F2:G2) -> 937.5 | I2: =AVERAGE(H2,H79) -> 1018.75
A3: 1974 | B3: VW | C3: Passat B1 | D3: 4200 | E3: 1620 | F3: 880 | G3: 995 | H3: =AVERAGE(F3:G3) -> 937.5 | I3: =AVERAGE(H3,H80) -> 1018.75
A4: 1975 | B4: VW | C4: Passat B1 | D4: 4200 | E4: 1620 | F4: 880 | G4: 995 | H4: =AVERAGE(F4:G4) -> 937.5 | I4: =AVERAGE(H4,H81) -> 1018.75
A5: 1976 | B5: VW | C5: Passat B1 | D5: 4200 | E5: 1620 | F5: 880 | G5: 995 | H5: =AVERAGE(F5:G5) -> 937.5 | I5: =AVERAGE(H5,H82) -> 1018.75
A6: 1977 | B6: VW | C6: Passat B1 | D6: 4200 | E6: 1620 | F6: 880 | G6: 995 | H6: =AVERAGE(F6:G6) -> 937.5 | I6: =AVERAGE(H6,H83) -> 1018.75
A7: 1978 | B7: VW | C7: Passat B1 | D7: 4200 | E7: 1620 | F7: 880 | G7: 995 | H7: =AVERAGE(F7:G7) -> 937.5 | I7: =AVERAGE(H7,H84) -> 1018.75
A8: 1979 | B8: VW | C8: Passat B1 | D8: 4200 | E8: 1620 | F8: 880 | G8: 995 | H8: =AVERAGE(F8:G8) -> 937.5 | I8: =AVERAGE(H8,H85) -> 1018.75
A9: 1980 | B9: VW | C9: Passat B1/B2 | D9: 4435-4540 | E9: 1685 | F9: 845 | G9: 1250 | H9: =AVERAGE(F9:G9) -> 1047.5 | I9: =AVERAGE(H9,H86) -> 1073.75
A10: 1981 | B10: VW | C10: Passat B2 | D10: 4435-4540 | E10: 1685 | F10: 845 | G10: 1250 | H10: =AVERAGE(F10:G10) -> 1047.5 | I10: =AVERAGE(H10,H87) -> 1073.75
A11: 1982 | B11: VW | C11: Passat B2 | D11: 4435-4540 | E11: 1685 | F11: 845 | G11: 1250 | H11: =AVERAGE(F11:G11) -> 1047.5 | I11: =AVERAGE(H11,H88) -> 1093.75
A12: 1983 | B12: VW | C12: Passat B2 | D12: 4435-4540 | E12: 1685 | F12: 845 | G12: 1250 | H12: =AVERAGE(F12:G12) -> 1047.5 | I12: =AVERAGE(H12,H89) -> 1093.75
A13: 1984 | B13: VW | C13: Passat B2 | D13: 4435-4540 | E13: 1685 | F13: 845 | G13: 1250 | H13: =AVERAGE(F13:G13) -> 1047.5 | I13: =AVERAGE(H13,H90) -> 1093.75
A14: 1985 | B14: VW | C14: Passat B2 | D14: 4435-4540 | E14: 1685 | F14: 845 | G14: 1250 | H14: =AVERAGE(F14:G14) -> 1047.5 | I14: =AVERAGE(H14,H91) -> 1093.75
A15: 1986 | B15: VW | C15: Passat B2 | D15: 4435-4540 | E15: 1685 | F15: 845 | G15: 1250 | H15: =AVERAGE(F15:G15) -> 1047.5 | I15: =AVERAGE(H15,H92) -> 1093.75
A16: 1987 | B16: VW | C16: Passat B2 | D16: 4435-4540 | E16: 1685 | F16: 845 | G16: 1250 | H16: =AVERAGE(F16:G16) -> 1047.5 | I16: =AVERAGE(H16,H93) -> 1093.75
A17: 1988 | B17: VW | C17: Passat B2/B3 | D17: 4575 | E17: 1705 | F17: 1130 | G17: 1380 | H17: =AVERAGE(F17:G17) -> 1255 | I17: =AVERAGE(H17,H54,H91) -> 1145
A18: 1989 | B18: VW | C18: Passat B3 | D18: 4575 | E18: 1705 | F18: 1130 | G18: 1380 | H18: =AVERAGE(F18:G18) -> 1255 | I18: =AVERAGE(H18,H55,H92) -> 1145
A19: 1990 | B19: VW | C19: Passat B3 | D19: 4575 | E19: 1705 | F19: 1130 | G19: 1380 | H19: =AVERAGE(F19:G19) -> 1255 | I19: =AVERAGE(H19,H56,H93) -> 1145
A20: 1991 | B20: VW | C20: Passat B3 | D20: 4575 | E20: 1705 | F20: 1130 | G20: 1380 | H20: =AVERAGE(F20:G20) -> 1255 | I20: =AVERAGE(H20,H57,H94) -> 1145
A21: 1992 | B21: VW | C21: Passat B3 | D21: 4575 | E21: 1705 | F21: 1130 | G21: 1380 | H21: =AVERAGE(F21:G21) -> 1255 | I21: =AVERAGE(H21,H58,H95) -> 1145
A22: 1993 | B22: VW | C22: Passat B3/B4 | D22: 4595-4605 | E22: 1720 | F22: 1210 | G22: 1445 | H22: =AVERAGE(F22:G22) -> 1327.5 | I22: =AVERAGE(H22,H59,H96) -> 1240.8333
A23: 1994 | B23: VW | C23: Passat B4 | D23: 4595-4605 | E23: 1720 | F23: 1210 | G23: 1445 | H23: =AVERAGE(F23:G23) -> 1327.5 | I23: =AVERAGE(H23,H60,H97) -> 1240.8333
A24: 1995 | B24: VW | C24: Passat B4 | D24: 4595-4605 | E24: 1720 | F24: 1210 | G24: 1445 | H24: =AVERAGE(F24:G24) -> 1327.5 | I24: =AVERAGE(H24,H61,H98) -> 1240.8333
A25: 1996 | B25: VW | C25: Passat B4/B5 | D25: 4669-4675 | E25: 1740 | F25: 1345 | G25: 1436 | H25: =AVERAGE(F25:G25) -> 1390.5 | I25: =AVERAGE(H25,H62,H99) -> 1357.6667
A26: 1997 | B26: VW | C26: Passat B4/B5 | D26: 4669-4675 | E26: 1740 | F26: 1345 | G26: 1436 | H26: =AVERAGE(F26:G26) -> 1390.5 | I26: =AVERAGE(H26,H63,H100) -> 1357.6667
A27: 1998 | B27: VW | C27: Passat B5 | D27: 4669-4675 | E27: 1740 | F27: 1345 | G27: 1436 | H27: =AVERAGE(F27:G27) -> 1390.5 | I27: =AVERAGE(H27,H64,H101) -> 1357.6667
A28: 1999 | B28: VW | C28: Passat B5 | D28: 4669-4675 | E28: 1740 | F28: 1345 | G28: 1436 | H28: =AVERAGE(F28:G28) -> 1390.5 | I28: =AVERAGE(H28,H65,H102) -> 1417.6667
A29: 2000 | B29: VW | C29: Passat B5 | D29: 4669-4675 | E29: 1740 | F29: 1345 | G29: 1436 | H29: =AVERAGE(F29:G29) -> 1390.5 | I29: =AVERAGE(H29,H66,H103) -> 1417.6667
A30: 2001 | B30: VW | C30: Passat B5 | D30: 4669-4675 | E30: 1740 | F30: 1345 | G30: 1436 | H30: =AVERAGE(F30:G30) -> 1390.5 | I30: =AVERAGE(H30,H67,H104) -> 1417.6667
A31: 2002 | B31: VW | C31: Passat B5 | D31: 4669-4675 | E31: 1740 | F31: 1345 | G31: 1436 | H31: =AVERAGE(F31:G31) -> 1390.5 | I31: =AVERAGE(H31,H68,H105) -> 1417.6667
A32: 2003 | B32: VW | C32: Passat B5 | D32: 4669-4675 | E32: 1740 | F32: 1345 | G32: 1436 | H32: =AVERAGE(F32:G32) -> 1390.5 | I32: =AVERAGE(H32,H69,H106) -> 1417.6667
A33: 2004 | B33: VW | C33: Passat B5 | D33: 4669-4675 | E33: 1740 | F33: 1345 | G33: 1436 | H33: =AVERAGE(F33:G33) -> 1390.5 | I33: =AVERAGE(H33,H70,H107) -> 1417.6667
... A40: 2011 | B40: VW | C40: Passat B7 | D40: 4769-4771 | E40: 1820 | F40: 1440 | G40: 1773 | H40: =AVERAGE(F40:G40) -> 1606.5 | I40: =AVERAGE(H40,H77,H114) -> 1628.8333
A41: 2012 | B41: VW | C41: Passat B7 | D41: 4769-4771 | E41: 1820 | F41: 1440 | G41: 1773 | H41: =AVERAGE(F41:G41) -> 1606.5 | I41: =AVERAGE(H41,H117) -> 1594.5
A42: 2013 | B42: VW | C42: Passat B7 | D42: 4769-4771 | E42: 1820 | F42: 1440 | G42: 1773 | H42: =AVERAGE(F42:G42) -> 1606.5 | I42: =AVERAGE(H42,H118) -> 1594.5
A43: 2014 | B43: VW | C43: Passat B7/B8 | D43: 4767-4777 | E43: 1832 | F43: 1367 | G43: 1776 | H43: =AVERAGE(F43:G43) -> 1571.5 | I43: =AVERAGE(H43,H119) -> 1577
A44: 2015 | B44: VW | C44: Passat B8 | D44: 4767-4777 | E44: 1832 | F44: 1367 | G44: 1776 | H44: =AVERAGE(F44:G44) -> 1571.5 | I44: =AVERAGE(H44,H120) -> 1577
A45: 2016 | B45: VW | C45: Passat B8 | D45: 4767-4777 | E45: 1832 | F45: 1367 | G45: 1776 | H45: =AVERAGE(F45:G45) -> 1571.5 | I45: =AVERAGE(H45,H121) -> 1577
A46: 2017 | B46: VW | C46: Passat B8 | D46: 4767-4777 | E46: 1832 | F46: 1367 | G46: 1776 | H46: =AVERAGE(F46:G46) -> 1571.5 | I46: =AVERAGE(H46,H122) -> 1577
...

Sheet SegmentE
A1: year | B1: campany | C1: type | D1: length | E1: width | F1: weightLow | G1: weightUp | H1: Mean Weight | I1: Mean Weigth Segment E
A2: 1979 | B2: Peugeot | C2: 505 | D2: 4600-4900 | E2: 1750 | F2: 1200 | G2: 1400 | H2: =AVERAGE(F2:G2) -> 1300
A3: 1980 | B3: Peugeot | C3: 505 | D3: 4600-4900 | E3: 1750 | F3: 1200 | G3: 1400 | H3: =AVERAGE(F3:G3) -> 1300
A4: 1981 | B4: Peugeot | C4: 505 | D4: 4600-4900 | E4: 1750 | F4: 1200 | G4: 1400 | H4: =AVERAGE(F4:G4) -> 1300
A5: 1982 | B5: Peugeot | C5: 505 | D5: 4600-4900 | E5: 1750 | F5: 1200 | G5: 1400 | H5: =AVERAGE(F5:G5) -> 1300
A6: 1983 | B6: Peugeot | C6: 505 | D6: 4600-4900 | E6: 1750 | F6: 1200 | G6: 1400 | H6: =AVERAGE(F6:G6) -> 1300
A7: 1984 | B7: Peugeot | C7: 505 | D7: 4600-4900 | E7: 1750 | F7: 1200 | G7: 1400 | H7: =AVERAGE(F7:G7) -> 1300
A8: 1985 | B8: Peugeot | C8: 505 | D8: 4600-4900 | E8: 1750 | F8: 1200 | G8: 1400 | H8: =AVERAGE(F8:G8) -> 1300
A9: 1986 | B9: Peugeot
A10: 1987 | B10: Peugeot
A11: 1988 | B11: Peugeot
A12: 1989 | B12: Peugeot | C12: 605 | D12: 4720 | E12: 1800 | F12: 1325 | G12: 1460 | H12: =AVERAGE(F12:G12) -> 1392.5
A13: 1990 | B13: Peugeot | C13: 605 | D13: 4720 | E13: 1800 | F13: 1325 | G13: 1460 | H13: =AVERAGE(F13:G13) -> 1392.5
A14: 1991 | B14: Peugeot | C14: 605 | D14: 4720 | E14: 1800 | F14: 1325 | G14: 1460 | H14: =AVERAGE(F14:G14) -> 1392.5
A15: 1992 | B15: Peugeot | C15: 605 | D15: 4720 | E15: 1800 | F15: 1325 | G15: 1460 | H15: =AVERAGE(F15:G15) -> 1392.5
A16: 1993 | B16: Peugeot | C16: 605 | D16: 4720 | E16: 1800 | F16: 1325 | G16: 1460 | H16: =AVERAGE(F16:G16) -> 1392.5
A17: 1994 | B17: Peugeot | C17: 605 | D17: 4720 | E17: 1800 | F17: 1325 | G17: 1460 | H17: =AVERAGE(F17:G17) -> 1392.5
A18: 1995 | B18: Peugeot | C18: 605 | D18: 4720 | E18: 1800 | F18: 1325 | G18: 1460 | H18: =AVERAGE(F18:G18) -> 1392.5
A19: 1996 | B19: Peugeot | C19: 605 | D19: 4720 | E19: 1800 | F19: 1325 | G19: 1460 | H19: =AVERAGE(F19:G19) -> 1392.5
A20: 1997 | B20: Peugeot | C20: 605 | D20: 4720 | E20: 1800 | F20: 1325 | G20: 1460 | H20: =AVERAGE(F20:G20) -> 1392.5
A21: 1998 | B21: Peugeot | C21: 605 | D21: 4720 | E21: 1800 | F21: 1325 | G21: 1460 | H21: =AVERAGE(F21:G21) -> 1392.5
A22: 1999 | B22: Peugeot | C22: 605 | D22: 4720 | E22: 1800 | F22: 1325 | G22: 1460 | H22: =AVERAGE(F22:G22) -> 1392.5
A23: 2000 | B23: Peugeot | C23: 607 | D23: 4902 | E23: 1835 | F23: 1610 | G23: 1798 | H23: =AVERAGE(F23:G23) -> 1704
... A32: 2009 | B32: Peugeot | C32: 607 | D32: 4902 | E32: 1835 | F32: 1610 | G32: 1798 | H32: =AVERAGE(F32:G32) -> 1704
A33: 2010 | B33: Peugeot | C33: 508/607 | D33: 4792-4830 | E33: 1853 | F33: 1390 | G33: 1910 | H33: =AVERAGE(F33:G33) -> 1650
A34: 2011 | B34: Peugeot | C34: 508 | D34: 4792-4830 | E34: 1853 | F34: 1390 | G34: 1910 | H34: =AVERAGE(F34:G34) -> 1650
A35: 2012 | B35: Peugeot | C35: 508 | D35: 4792-4830 | E35: 1853 | F35: 1390 | G35: 1910 | H35: =AVERAGE(F35:G35) -> 1650
A36: 2013 | B36: Peugeot | C36: 508 | D36: 4792-4830 | E36: 1853 | F36: 1390 | G36: 1910 | H36: =AVERAGE(F36:G36) -> 1650
A37: 2014 | B37: Peugeot | C37: 508 | D37: 4792-4830 | E37: 1853 | F37: 1390 | G37: 1910 | H37: =AVERAGE(F37:G37) -> 1650
A38: 2015 | B38: Peugeot | C38: 508 | D38: 4792-4830 | E38: 1853 | F38: 1390 | G38: 1910 | H38: =AVERAGE(F38:G38) -> 1650
A39: 2016 | B39: Peugeot | C39: 508 | D39: 4792-4830 | E39: 1853 | F39: 1390 | G39: 1910 | H39: =AVERAGE(F39:G39) -> 1650
A40: 2017 | B40: Peugeot | C40: 508 | D40: 4792-4830 | E40: 1853 | F40: 1390 | G40: 1910 | H40: =AVERAGE(F40:G40) -> 1650
A41: 2018 | B41: Peugeot | C41: 508 I/II | D41: 4750-4870 | E41: 1855-1859 | F41: 1478 | G41: 1610 | H41: =AVERAGE(F41:G41) -> 1544
A42: 2019 | B42: Peugeot | C42: 508 II | D42: 4750-4870 | E42: 1855-1859 | F42: 1478 | G42: 1610 | H42: =AVERAGE(F42:G42) -> 1544
A43: 2020 | B43: Peugeot | C43: 508 II | D43: 4750-4870 | E43: 1855-1859 | F43: 1478 | G43: 1610 | H43: =AVERAGE(F43:G43) -> 1544
A44: 2021 | B44: Peugeot | C44: 508 II | D44: 4750-4870 | E44: 1855-1859 | F44: 1478 | G44: 1610 | H44: =AVERAGE(F44:G44) -> 1544
A45: 2022 | B45: Peugeot | C45: 508 II | D45: 4750-4870 | E45: 1855-1859 | F45: 1478 | G45: 1610 | H45: =AVERAGE(F45:G45) -> 1544
A46: 2023 | B46: Peugeot | C46: 508 II | D46: 4750-4870 | E46: 1855-1859 | F46: 1478 | G46: 1610 | H46: =AVERAGE(F46:G46) -> 1544
A47: 2024 | B47: Peugeot | C47: 508 II | D47: 4750-4870 | E47: 1855-1859 | F47: 1478 | G47: 1610 | H47: =AVERAGE(F47:G47) -> 1544
A48: 1975 | B48: BMW | C48: 5 Series (E12) | D48: 4620 | E48: 1690 | F48: 1233 | G48: 1495 | H48: =AVERAGE(F48:G48) -> 1364 | I48: =AVERAGE(H48) -> 1364
...

Sheet SegmentF
A1: year | B1: campany | C1: type | D1: length | E1: width | F1: weightLow | G1: weightUp | H1: Mean Weight | I1: Mean Weight Segment F
A2: 1975 | B2: BMW | C2: 7 Series (E23) | D2: 4860-5014 | E2: 1800 | F2: 1470 | G2: 1629 | H2: =AVERAGE(F2:G2) -> 1549.5 | I2: =H2 -> 1549.5
A3: 1976 | B3: BMW | C3: 7 Series (E23) | D3: 4860-5014 | E3: 1800 | F3: 1470 | G3: 1629 | H3: =AVERAGE(F3:G3) -> 1549.5 | I3: =H3 -> 1549.5
A4: 1977 | B4: BMW | C4: 7 Series (E23) | D4: 4860-5014 | E4: 1800 | F4: 1470 | G4: 1629 | H4: =AVERAGE(F4:G4) -> 1549.5 | I4: =H4 -> 1549.5
A5: 1978 | B5: BMW | C5: 7 Series (E23) | D5: 4860-5014 | E5: 1800 | F5: 1470 | G5: 1629 | H5: =AVERAGE(F5:G5) -> 1549.5 | I5: =H5 -> 1549.5
A6: 1979 | B6: BMW | C6: 7 Series (E23) | D6: 4860-5014 | E6: 1800 | F6: 1470 | G6: 1629 | H6: =AVERAGE(F6:G6) -> 1549.5 | I6: =H6 -> 1549.5
A7: 1980 | B7: BMW | C7: 7 Series (E23) | D7: 4860-5014 | E7: 1800 | F7: 1470 | G7: 1629 | H7: =AVERAGE(F7:G7) -> 1549.5 | I7: =H7 -> 1549.5
A8: 1981 | B8: BMW | C8: 7 Series (E23) | D8: 4860-5014 | E8: 1800 | F8: 1470 | G8: 1629 | H8: =AVERAGE(F8:G8) -> 1549.5 | I8: =H8 -> 1549.5
A9: 1982 | B9: BMW | C9: 7 Series (E23) | D9: 4860-5014 | E9: 1800 | F9: 1470 | G9: 1629 | H9: =AVERAGE(F9:G9) -> 1549.5 | I9: =H9 -> 1549.5
A10: 1983 | B10: BMW | C10: 7 Series (E23) | D10: 4860-5014 | E10: 1800 | F10: 1470 | G10: 1629 | H10: =AVERAGE(F10:G10) -> 1549.5 | I10: =H10 -> 1549.5
A11: 1984 | B11: BMW | C11: 7 Series (E23) | D11: 4860-5014 | E11: 1800 | F11: 1470 | G11: 1629 | H11: =AVERAGE(F11:G11) -> 1549.5 | I11: =H11 -> 1549.5
A12: 1985 | B12: BMW | C12: 7 Series (E23) | D12: 4860-5014 | E12: 1800 | F12: 1470 | G12: 1629 | H12: =AVERAGE(F12:G12) -> 1549.5 | I12: =H12 -> 1549.5
A13: 1986 | B13: BMW | C13: 7 Series (E23) | D13: 4860-5014 | E13: 1800 | F13: 1470 | G13: 1629 | H13: =AVERAGE(F13:G13) -> 1549.5 | I13: =H13 -> 1549.5
... A49: 2022 | B49: BMW | C49: 7 Series (G11) | D49: 5098-5268 | E49: 1902 | F49: 1755 | G49: 2255 | H49: =AVERAGE(F49:G49) -> 2005 | I49: =H49 -> 2005
A50: 2023 | B50: BMW | C50: 7 Series (G70) | D50: 5391 | E50: 1950 | F50: 2075 | G50: 2770 | H50: =AVERAGE(F50:G50) -> 2422.5 | I50: =H50 -> 2422.5
A51: 2024 | B51: BMW | C51: 7 Series (G70) | D51: 5391 | E51: 1950 | F51: 2075 | G51: 2770 | H51: =AVERAGE(F51:G51) -> 2422.5 | I51: =H51 -> 2422.5

Sheet EuroStat
A1: weightLow | B1: weightHigh | C1: Range
B2: 999 | C2: 1
A3: 1000 | B3: 1249 | C3: 2
A4: 1250 | B4: 1499 | C4: 3
A5: 1500 | C5: 4

Sheet TranslateKeys
A1: FuturamKey-Petrol | B1: InternalKey
A2: V0101010000 | B2: vPetrolStandard
A3: V0101010101 | B3: vPetrolA
A4: V0101010102 | B4: vPetrolB
A5: V0101010103 | B5: vPetrolC
A6: V0101010104 | B6: vPetrolD
A7: V0101010105 | B7: vPetrolE
A8: V0101010106 | B8: vPetrolF
A9: V0101010201 | B9: vPetrolJA
A10: V0101010202 | B10: vPetrolJB
A11: V0101010203 | B11: vPetrolJC
A12: V0101010204 | B12: vPetrolJD
... A53: V0401010206 | B53: vHEVJF

Sheet Keys
A1: Year | B1: Weight Standard | C1: Standard Weight Rang | D1: Weight Segment A | E1: Segement A Weight Range | F1: Weight Segment B | G1: Segment B Weight Range | H1: Weight Segment C | I1: Segment C Weight Rang | J1: Weight Segment D | K1: Segment D Weight Range | L1: Weight Segment E | M1: Segment E Weight Range | N1: Weight Segment F | O1: Segment F Weight Range | P1: JRC_V01010001 | Q1: JRC_V01010101 | R1: JRC_V01010201 | S1: JRC_V01010301 | T1: JRC_V01010002 | U1: JRC_V01010102 | V1: JRC_V01010202 | W1: JRC_V01010302 | X1: JRC_V01010003 | Y1: JRC_V01010103 | Z1: JRC_V01010203 | AA1: JRC_V01010303 | AB1: JRC_V01010004 | AC1: JRC_V01010104 | AD1: JRC_V01010204 | AE1: JRC_V01010304 | AF1: V0101010100 - Standard Pertoleum Car | AG1: JRC_V01070000 | AH1: JRC_V01070001 | AI1: JRC_V01070002 | AJ1: JRC_V01070003 | AK1: JRC_V01070004 | AL1: JRC_V01070400 | AM1: JRC_V01070401 | AN1: JRC_V01070402 | AO1: JRC_V01070403 | AP1: JRC_V01070304 | AQ1: JRC_V01050000 | AR1: JRC_V01050101 | AS1: JRC_V01050102 | AT1: JRC_V01050103 | AU1: JRC_V01050104 | AV1: JRC_V01050201 | AW1: JRC_V01050202 | AX1: JRC_V01050203 | AY1: JRC_V01050204 | AZ1: JRC_V01050301 | BA1: JRC_V01050302 | BB1: JRC_V01050303 | BC1: JRC_V01050304 | BD1: JRC_V01060000 | BE1: JRC_V01060101 | BF1: JRC_V01060102 | BG1: JRC_V01060103 | BH1: JRC_V01060104 | BI1: JRC_V01060201 | BJ1: JRC_V01060202 | BK1: JRC_V01060203 | BL1: JRC_V01060204 | BM1: JRC_V01060301 | BN1: JRC_V01060302 | BO1: JRC_V01060303 | BP1: JRC_V01060304
A2: 1975 | B2: =AVERAGE(F2,H2,J2,L2,N2) -> 1108.3667 | C2: 2 | E2: 1 | F2: =SegmentB!I2 -> 741.25 | G2: 1 | H2: ='Segment C'!I3 -> 868.33333 | I2: 1 | J2: =SegmentD!I4 -> 1018.75 | K2: 2 | L2: =SegmentE!I48 -> 1364 | M2: 3 | N2: =SegmentF!I2 -> 1549.5 | O2: 4 | P2: V0101010101;V0101010102;V0101010103 | Q2: V0101010101;V0101010102;V0101010103 | R2: V0101010101;V0101010102;V0101010103 | S2: V0101010101;V0101010102;V0101010103 | T2: V0101010104 | U2: V0101010104 | V2: V0101010104 | W2: V0101010104 | X2: V0101010105 | Y2: V0101010105 | Z2: V0101010105 | AA2: V0101010105 | AB2: V0101010106 | AC2: V0101010106 | AD2: V0101010106 | AE2: V0101010106 | AF2: It includes all JRC codes for petroleum Cars
A3: 1976 | B3: =AVERAGE(F3,H3,J3,L3,N3) -> 1108.3667 | C3: 2 | E3: 1 | F3: =SegmentB!I3 -> 741.25 | G3: 1 | H3: ='Segment C'!I4 -> 868.33333 | I3: 1 | J3: =SegmentD!I5 -> 1018.75 | K3: 2 | L3: =SegmentE!I49 -> 1364 | M3: 3 | N3: =SegmentF!I3 -> 1549.5 | O3: 4 | P3: V0101010101;V0101010102;V0101010103 | Q3: V0101010101;V0101010102;V0101010103 | R3: V0101010101;V0101010102;V0101010103 | S3: V0101010101;V0101010102;V0101010103 | T3: V0101010104 | U3: V0101010104 | V3: V0101010104 | W3: V0101010104 | X3: V0101010105 | Y3: V0101010105 | Z3: V0101010105 | AA3: V0101010105 | AB3: V0101010106 | AC3: V0101010106 | AD3: V0101010106 | AE3: V0101010106
A4: 1977 | B4: =AVERAGE(F4,H4,J4,L4,N4) -> 1108.3667 | C4: 2 | E4: 1 | F4: =SegmentB!I4 -> 741.25 | G4: 1 | H4: ='Segment C'!I5 -> 868.33333 | I4: 1 | J4: =SegmentD!I6 -> 1018.75 | K4: 2 | L4: =SegmentE!I50 -> 1364 | M4: 3 | N4: =SegmentF!I4 -> 1549.5 | O4: 4 | P4: V0101010101;V0101010102;V0101010103 | Q4: V0101010101;V0101010102;V0101010103 | R4: V0101010101;V0101010102;V0101010103 | S4: V0101010101;V0101010102;V0101010103 | T4: V0101010104 | U4: V0101010104 | V4: V0101010104 | W4: V0101010104 | X4: V0101010105 | Y4: V0101010105 | Z4: V0101010105 | AA4: V0101010105 | AB4: V0101010106 | AC4: V0101010106 | AD4: V0101010106 | AE4: V0101010106
A5: 1978 | B5: =AVERAGE(F5,H5,J5,L5,N5) -> 1108.3667 | C5: 2 | E5: 1 | F5: =SegmentB!I5 -> 741.25 | G5: 1 | H5: ='Segment C'!I6 -> 868.33333 | I5: 1 | J5: =SegmentD!I7 -> 1018.75 | K5: 2 | L5: =SegmentE!I51 -> 1364 | M5: 3 | N5: =SegmentF!I5 -> 1549.5 | O5: 4 | P5: V0101010101;V0101010102;V0101010103 | Q5: V0101010101;V0101010102;V0101010103 | R5: V0101010101;V0101010102;V0101010103 | S5: V0101010101;V0101010102;V0101010103 | T5: V0101010104 | U5: V0101010104 | V5: V0101010104 | W5: V0101010104 | X5: V0101010105 | Y5: V0101010105 | Z5: V0101010105 | AA5: V0101010105 | AB5: V0101010106 | AC5: V0101010106 | AD5: V0101010106 | AE5: V0101010106
A6: 1979 | B6: =AVERAGE(F6,H6,J6,L6,N6) -> 1108.3667 | C6: 2 | E6: 1 | F6: =SegmentB!I6 -> 741.25 | G6: 1 | H6: ='Segment C'!I7 -> 868.33333 | I6: 1 | J6: =SegmentD!I8 -> 1018.75 | K6: 2 | L6: =SegmentE!I52 -> 1364 | M6: 3 | N6: =SegmentF!I6 -> 1549.5 | O6: 4 | P6: V0101010101;V0101010102;V0101010103 | Q6: V0101010101;V0101010102;V0101010103 | R6: V0101010101;V0101010102;V0101010103 | S6: V0101010101;V0101010102;V0101010103 | T6: V0101010104 | U6: V0101010104 | V6: V0101010104 | W6: V0101010104 | X6: V0101010105 | Y6: V0101010105 | Z6: V0101010105 | AA6: V0101010105 | AB6: V0101010106 | AC6: V0101010106 | AD6: V0101010106 | AE6: V0101010106
A7: 1980 | B7: =AVERAGE(F7,H7,J7,L7,N7) -> 1113.8 | C7: 2 | E7: 1 | F7: =SegmentB!I7 -> 741.25 | G7: 1 | H7: ='Segment C'!I8 -> 872.5 | I7: 1 | J7: =SegmentD!I9 -> 1073.75 | K7: 2 | L7: =SegmentE!I53 -> 1332 | M7: 3 | N7: =SegmentF!I7 -> 1549.5 | O7: 4 | P7: V0101010101;V0101010102;V0101010103 | Q7: V0101010101;V0101010102;V0101010103 | R7: V0101010101;V0101010102;V0101010103 | S7: V0101010101;V0101010102;V0101010103 | T7: V0101010104 | U7: V0101010104 | V7: V0101010104 | W7: V0101010104 | X7: V0101010105 | Y7: V0101010105 | Z7: V0101010105 | AA7: V0101010105 | AB7: V0101010106 | AC7: V0101010106 | AD7: V0101010106 | AE7: V0101010106
A8: 1981 | B8: =AVERAGE(F8,H8,J8,L8,N8) -> 1122.3 | C8: 2 | E8: 1 | F8: =SegmentB!I8 -> 783.75 | G8: 1 | H8: ='Segment C'!I9 -> 872.5 | I8: 1 | J8: =SegmentD!I10 -> 1073.75 | K8: 2 | L8: =SegmentE!I54 -> 1332 | M8: 3 | N8: =SegmentF!I8 -> 1549.5 | O8: 4 | P8: V0101010101;V0101010102;V0101010103 | Q8: V0101010101;V0101010102;V0101010103 | R8: V0101010101;V0101010102;V0101010103 | S8: V0101010101;V0101010102;V0101010103 | T8: V0101010104 | U8: V0101010104 | V8: V0101010104 | W8: V0101010104 | X8: V0101010105 | Y8: V0101010105 | Z8: V0101010105 | AA8: V0101010105 | AB8: V0101010106 | AC8: V0101010106 | AD8: V0101010106 | AE8: V0101010106
A9: 1982 | B9: =AVERAGE(F9,H9,J9,L9,N9) -> 1144.6 | C9: 2 | E9: 1 | F9: =SegmentB!I9 -> 783.75 | G9: 1 | H9: ='Segment C'!I10 -> 872.5 | I9: 1 | J9: =SegmentD!I11 -> 1093.75 | K9: 2 | L9: =SegmentE!I55 -> 1423.5 | M9: 3 | N9: =SegmentF!I9 -> 1549.5 | O9: 4 | P9: V0101010101;V0101010102;V0101010103 | Q9: V0101010101;V0101010102;V0101010103 | R9: V0101010101;V0101010102;V0101010103 | S9: V0101010101;V0101010102;V0101010103 | T9: V0101010104 | U9: V0101010104 | V9: V0101010104 | W9: V0101010104 | X9: V0101010105 | Y9: V0101010105 | Z9: V0101010105 | AA9: V0101010105 | AB9: V0101010106 | AC9: V0101010106 | AD9: V0101010106 | AE9: V0101010106
A10: 1983 | B10: =AVERAGE(F10,H10,J10,L10,N10) -> 1161.2667 | C10: 2 | E10: 1 | F10: =SegmentB!I10 -> 788.75 | G10: 1 | H10: ='Segment C'!I11 -> 950.83333 | I10: 1 | J10: =SegmentD!I12 -> 1093.75 | K10: 2 | L10: =SegmentE!I56 -> 1423.5 | M10: 3 | N10: =SegmentF!I10 -> 1549.5 | O10: 4 | P10: V0101010101;V0101010102;V0101010103 | Q10: V0101010101;V0101010102;V0101010103 | R10: V0101010101;V0101010102;V0101010103 | S10: V0101010101;V0101010102;V0101010103 | T10: V0101010104 | U10: V0101010104 | V10: V0101010104 | W10: V0101010104 | X10: V0101010105 | Y10: V0101010105 | Z10: V0101010105 | AA10: V0101010105 | AB10: V0101010106 | AC10: V0101010106 | AD10: V0101010106 | AE10: V0101010106
A11: 1984 | B11: =AVERAGE(F11,H11,J11,L11,N11) -> 1161.2667 | C11: 2 | E11: 1 | F11: =SegmentB!I11 -> 788.75 | G11: 1 | H11: ='Segment C'!I12 -> 950.83333 | I11: 1 | J11: =SegmentD!I13 -> 1093.75 | K11: 2 | L11: =SegmentE!I57 -> 1423.5 | M11: 3 | N11: =SegmentF!I11 -> 1549.5 | O11: 4 | P11: V0101010101;V0101010102;V0101010103 | Q11: V0101010101;V0101010102;V0101010103 | R11: V0101010101;V0101010102;V0101010103 | S11: V0101010101;V0101010102;V0101010103 | T11: V0101010104 | U11: V0101010104 | V11: V0101010104 | W11: V0101010104 | X11: V0101010105 | Y11: V0101010105 | Z11: V0101010105 | AA11: V0101010105 | AB11: V0101010106 | AC11: V0101010106 | AD11: V0101010106 | AE11: V0101010106
A12: 1985 | B12: =AVERAGE(F12,H12,J12,L12,N12) -> 1158.2667 | C12: 2 | E12: 1 | F12: =SegmentB!I12 -> 788.75 | G12: 1 | H12: ='Segment C'!I13 -> 935.83333 | I12: 1 | J12: =SegmentD!I14 -> 1093.75 | K12: 2 | L12: =SegmentE!I58 -> 1423.5 | M12: 3 | N12: =SegmentF!I12 -> 1549.5 | O12: 4 | P12: V0101010101;V0101010102;V0101010103 | Q12: V0101010101;V0101010102;V0101010103 | R12: V0101010101;V0101010102;V0101010103 | S12: V0101010101;V0101010102;V0101010103 | T12: V0101010104 | U12: V0101010104 | V12: V0101010104 | W12: V0101010104 | X12: V0101010105 | Y12: V0101010105 | Z12: V0101010105 | AA12: V0101010105 | AB12: V0101010106 | AC12: V0101010106 | AD12: V0101010106 | AE12: V0101010106
A13: 1986 | B13: =AVERAGE(F13,H13,J13,L13,N13) -> 1182.9667 | C13: 2 | E13: 1 | F13: =SegmentB!I13 -> 788.75 | G13: 1 | H13: ='Segment C'!I14 -> 935.83333 | I13: 1 | J13: =SegmentD!I15 -> 1093.75 | K13: 2 | L13: =SegmentE!I59 -> 1547 | M13: 4 | N13: =SegmentF!I13 -> 1549.5 | O13: 4 | P13: V0101010101;V0101010102;V0101010103 | Q13: V0101010101;V0101010102;V0101010103 | R13: V0101010101;V0101010102;V0101010103 | S13: V0101010101;V0101010102;V0101010103 | T13: V0101010104 | U13: V0101010104 | V13: V0101010104 | W13: V0101010104 | X13: V0101010105 | Y13: V0101010105 | Z13: V0101010105 | AA13: V0101010105 | AB13: V0101010106;V0101010105 | AC13: V0101010106;V0101010105 | AD13: V0101010106;V0101010105 | AE13: V0101010106;V0101010105
A14: 1987 | B14: =AVERAGE(F14,H14,J14,L14,N14) -> 1238.0667 | C14: 2 | E14: 1 | F14: =SegmentB!I14 -> 788.75 | G14: 1 | H14: ='Segment C'!I15 -> 935.83333 | I14: 1 | J14: =SegmentD!I16 -> 1093.75 | K14: 2 | L14: =SegmentE!I60 -> 1547 | M14: 4 | N14: =SegmentF!I14 -> 1825 | O14: 4 | P14: V0101010101;V0101010102;V0101010103 | Q14: V0101010101;V0101010102;V0101010103 | R14: V0101010101;V0101010102;V0101010103 | S14: V0101010101;V0101010102;V0101010103 | T14: V0101010104 | U14: V0101010104 | V14: V0101010104 | W14: V0101010104 | X14: V0101010105 | Y14: V0101010105 | Z14: V0101010105 | AA14: V0101010105 | AB14: V0101010106;V0101010105 | AC14: V0101010106;V0101010105 | AD14: V0101010106;V0101010105 | AE14: V0101010106;V0101010105
... A24: 1997 | B24: =AVERAGE(F24,H24,J24,L24,N24) -> 1384.3167 | C24: 3 | E24: 1 | F24: =SegmentB!I24 -> 896.5 | G24: 1 | H24: ='Segment C'!I25 -> 1191.1667 | I24: 2 | J24: =SegmentD!I26 -> 1357.6667 | K24: 3 | L24: =SegmentE!I70 -> 1578.75 | M24: 4 | N24: =SegmentF!I24 -> 1897.5 | O24: 4 | P24: V0101010101;V0101010102 | Q24: V0101010101;V0101010102 | R24: V0101010101;V0101010102 | S24: V0101010101;V0101010102 | T24: V0101010103 | U24: V0101010103 | V24: V0101010103 | W24: V0101010103 | X24: V0101010104 | Y24: V0101010104 | Z24: V0101010104 | AA24: V0101010104 | AB24: V0101010106;V0101010105 | AC24: V0101010106;V0101010105 | AD24: V0101010106;V0101010105 | AE24: V0101010106;V0101010105
A25: 1998 | B25: =AVERAGE(F25,H25,J25,L25,N25) -> 1417.8167 | C25: 3 | E25: 1 | F25: =SegmentB!I25 -> 1064 | G25: 2 | H25: ='Segment C'!I26 -> 1191.1667 | I25: 2 | J25: =SegmentD!I27 -> 1357.6667 | K25: 3 | L25: =SegmentE!I71 -> 1578.75 | M25: 4 | N25: =SegmentF!I25 -> 1897.5 | O25: 4 | P25: V0101010101 | Q25: V0101010101 | R25: V0101010101 | S25: V0101010101;V0101010103 | T25: V0101010103;V0101010102 | U25: V0101010103;V0101010102 | V25: V0101010103;V0101010102 | W25: V0101010103;V0101010102 | X25: V0101010104 | Y25: V0101010104 | Z25: V0101010104 | AA25: V0101010104 | AB25: V0101010106;V0101010105 | AC25: V0101010106;V0101010105 | AD25: V0101010106;V0101010105 | AE25: V0101010106;V0101010105 | AQ25: V0401010000;V0401010101;V04010100102;V0401010103;V0401010104;V0401010105;V0401010106;V0401010201;V0401010202;V0401010203;V0401010204;V0401010205;V0401010206 | AR25: V0401010101 | AS25: V0401010102;V0401010103 | AT25: V0401010104 | AU25: V0401010105;V0401010106 | AV25: V0401010101 | AW25: V0401010102;V0401010103 | AX25: V0401010104 | AY25: V0401010105;V0401010106 | AZ25: V0401010101 | BA25: V0401010102;V0401010103 | BB25: V0401010104;V0401010204 | BC25: V0401010105;V0401010106;V0401010205;V0401010206
A26: 1999 | B26: =AVERAGE(F26,H26,J26,L26,N26) -> 1435.1 | C26: 3 | E26: 1 | F26: =SegmentB!I26 -> 1101.25 | G26: 2 | H26: ='Segment C'!I27 -> 1180.3333 | I26: 2 | J26: =SegmentD!I28 -> 1417.6667 | K26: 3 | L26: =SegmentE!I72 -> 1578.75 | M26: 4 | N26: =SegmentF!I26 -> 1897.5 | O26: 4 | P26: V0101010101 | Q26: V0101010101 | R26: V0101010101 | S26: V0101010101 | T26: V0101010103;V0101010102 | U26: V0101010103;V0101010102 | V26: V0101010103;V0101010102 | W26: V0101010103;V0101010102 | X26: V0101010104 | Y26: V0101010104 | Z26: V0101010104 | AA26: V0101010104 | AB26: V0101010106;V0101010105 | AC26: V0101010106;V0101010105 | AD26: V0101010106;V0101010105 | AE26: V0101010106;V0101010105 | AQ26: V0401010000;V0401010101;V04010100102;V0401010103;V0401010104;V0401010105;V0401010106;V0401010201;V0401010202;V0401010203;V0401010204;V0401010205;V0401010206 | AR26: V0401010101 | AS26: V0401010102;V0401010103 | AT26: V0401010104 | AU26: V0401010105;V0401010106 | AV26: V0401010101 | AW26: V0401010102;V0401010103 | AX26: V0401010104 | AY26: V0401010105;V0401010106 | AZ26: V0401010101 | BA26: V0401010102;V0401010103 | BB26: V0401010104;V0401010204 | BC26: V0401010105;V0401010106;V0401010205;V0401010206
A27: 2000 | B27: =AVERAGE(F27,H27,J27,L27,N27) -> 1466.25 | C27: 3 | E27: 1 | F27: =SegmentB!I27 -> 1101.25 | G27: 2 | H27: ='Segment C'!I28 -> 1180.3333 | I27: 2 | J27: =SegmentD!I29 -> 1417.6667 | K27: 3 | L27: =SegmentE!I73 -> 1734.5 | M27: 4 | N27: =SegmentF!I27 -> 1897.5 | O27: 4 | P27: V0101010101 | Q27: V0101010101 | R27: V0101010101 | S27: V0101010101 | T27: V0101010103;V0101010102 | U27: V0101010103;V0101010102 | V27: V0101010103;V0101010102 | W27: V0101010103;V0101010102 | X27: V0101010104 | Y27: V0101010104 | Z27: V0101010104 | AA27: V0101010104 | AB27: V0101010106;V0101010105 | AC27: V0101010106;V0101010105 | AD27: V0101010106;V0101010105 | AE27: V0101010106;V0101010105 | AQ27: V0401010000;V0401010101;V04010100102;V0401010103;V0401010104;V0401010105;V0401010106;V0401010201;V0401010202;V0401010203;V0401010204;V0401010205;V0401010206 | AR27: V0401010101 | AS27: V0401010102;V0401010103 | AT27: V0401010104 | AU27: V0401010105;V0401010106 | AV27: V0401010101 | AW27: V0401010102;V0401010103 | AX27: V0401010104 | AY27: V0401010105;V0401010106 | AZ27: V0401010101 | BA27: V0401010102;V0401010103 | BB27: V0401010104;V0401010204 | BC27: V0401010105;V0401010106;V0401010205;V0401010206
A28: 2001 | B28: =AVERAGE(F28,H28,J28,L28,N28) -> 1486.65 | C28: 3 | E28: 1 | F28: =SegmentB!I28 -> 1101.25 | G28: 2 | H28: ='Segment C'!I29 -> 1304.8333 | I28: 3 | J28: =SegmentD!I30 -> 1417.6667 | K28: 3 | L28: =SegmentE!I74 -> 1734.5 | M28: 4 | N28: =SegmentF!I28 -> 1875 | O28: 4 | P28: V0101010101 | Q28: V0101010101 | R28: V0101010101 | S28: V0101010101 | T28: V0101010102 | U28: V0101010102 | V28: V0101010102 | W28: V0101010102 | X28: V0101010104;V0101010103 | Y28: V0101010104;V0101010103 | Z28: V0101010104;V0101010103 | AA28: V0101010104;V0101010103 | AB28: V0101010106;V0101010105 | AC28: V0101010106;V0101010105 | AD28: V0101010106;V0101010105 | AE28: V0101010106;V0101010105 | AQ28: V0401010000;V0401010101;V04010100102;V0401010103;V0401010104;V0401010105;V0401010106;V0401010201;V0401010202;V0401010203;V0401010204;V0401010205;V0401010206 | AR28: V0401010101 | AS28: V0401010102;V0401010103 | AT28: V0401010104 | AU28: V0401010105;V0401010106 | AV28: V0401010101 | AW28: V0401010102;V0401010103 | AX28: V0401010104 | AY28: V0401010105;V0401010106 | AZ28: V0401010101 | BA28: V0401010102;V0401010103 | BB28: V0401010104;V0401010204 | BC28: V0401010105;V0401010106;V0401010205;V0401010206
A29: 2002 | B29: =AVERAGE(F29,H29,J29,L29,N29) -> 1486.65 | C29: 3 | E29: 1 | F29: =SegmentB!I29 -> 1101.25 | G29: 2 | H29: ='Segment C'!I30 -> 1304.8333 | I29: 3 | J29: =SegmentD!I31 -> 1417.6667 | K29: 3 | L29: =SegmentE!I75 -> 1734.5 | M29: 4 | N29: =SegmentF!I29 -> 1875 | O29: 4 | P29: V0101010101 | Q29: V0101010101 | R29: V0101010101 | S29: V0101010101 | T29: V0101010102 | U29: V0101010102 | V29: V0101010102 | W29: V0101010102 | X29: V0101010104;V0101010103 | Y29: V0101010104;V0101010103 | Z29: V0101010104;V0101010103 | AA29: V0101010104;V0101010103 | AB29: V0101010106;V0101010105 | AC29: V0101010106;V0101010105 | AD29: V0101010106;V0101010105 | AE29: V0101010106;V0101010105 | AQ29: V0401010000;V0401010101;V04010100102;V0401010103;V0401010104;V0401010105;V0401010106;V0401010201;V0401010202;V0401010203;V0401010204;V0401010205;V0401010206 | AR29: V0401010101 | AS29: V0401010102;V0401010103 | AT29: V0401010104 | AU29: V0401010105;V0401010106 | AV29: V0401010101 | AW29: V0401010102;V0401010103 | AX29: V0401010104 | AY29: V0401010105;V0401010106 | AZ29: V0401010101 | BA29: V0401010102;V0401010103 | BB29: V0401010104;V0401010204 | BC29: V0401010105;V0401010106;V0401010205;V0401010206
A30: 2003 | B30: =AVERAGE(F30,H30,J30,L30,N30) -> 1493.9167 | C30: 3 | E30: 1 | F30: =SegmentB!I30 -> 1101.25 | G30: 2 | H30: ='Segment C'!I31 -> 1341.1667 | I30: 3 | J30: =SegmentD!I32 -> 1417.6667 | K30: 3 | L30: =SegmentE!I76 -> 1734.5 | M30: 4 | N30: =SegmentF!I30 -> 1875 | O30: 4 | P30: V0101010101 | Q30: V0101010101 | R30: V0101010101 | S30: V0101010101 | T30: V0101010102 | U30: V0101010102 | V30: V0101010102 | W30: V0101010102 | X30: V0101010104;V0101010103 | Y30: V0101010104;V0101010103 | Z30: V0101010104;V0101010103 | AA30: V0101010104;V0101010103 | AB30: V0101010106;V0101010105 | AC30: V0101010106;V0101010105 | AD30: V0101010106;V0101010105 | AE30: V0101010106;V0101010105 | AQ30: V0401010000;V0401010101;V04010100102;V0401010103;V0401010104;V0401010105;V0401010106;V0401010201;V0401010202;V0401010203;V0401010204;V0401010205;V0401010206 | AR30: V0401010101 | AS30: V0401010102;V0401010103 | AT30: V0401010104 | AU30: V0401010105;V0401010106 | AV30: V0401010101 | AW30: V0401010102;V0401010103 | AX30: V0401010104 | AY30: V0401010105;V0401010106 | AZ30: V0401010101 | BA30: V0401010102;V0401010103 | BB30: V0401010104;V0401010204 | BC30: V0401010105;V0401010106;V0401010205;V0401010206
A31: 2004 | B31: =AVERAGE(F31,H31,J31,L31,N31) -> 1486.1667 | C31: 3 | E31: 1 | F31: =SegmentB!I31 -> 1101.25 | G31: 2 | H31: ='Segment C'!I32 -> 1341.1667 | I31: 3 | J31: =SegmentD!I33 -> 1417.6667 | K31: 3 | L31: =SegmentE!I77 -> 1695.75 | M31: 4 | N31: =SegmentF!I31 -> 1875 | O31: 4 | P31: V0101010101 | Q31: V0101010101 | R31: V0101010101 | S31: V0101010101 | T31: V0101010102 | U31: V0101010102 | V31: V0101010102 | W31: V0101010102 | X31: V0101010104;V0101010103 | Y31: V0101010104;V0101010103 | Z31: V0101010104;V0101010103 | AA31: V0101010104;V0101010103 | AB31: V0101010106;V0101010105 | AC31: V0101010106;V0101010105 | AD31: V0101010106;V0101010105 | AE31: V0101010106;V0101010105 | AQ31: V0401010000;V0401010101;V04010100102;V0401010103;V0401010104;V0401010105;V0401010106;V0401010201;V0401010202;V0401010203;V0401010204;V0401010205;V0401010206 | AR31: V0401010101 | AS31: V0401010102;V0401010103 | AT31: V0401010104 | AU31: V0401010105;V0401010106 | AV31: V0401010101 | AW31: V0401010102;V0401010103 | AX31: V0401010104 | AY31: V0401010105;V0401010106 | AZ31: V0401010101 | BA31: V0401010102;V0401010103 | BB31: V0401010104;V0401010204 | BC31: V0401010105;V0401010106;V0401010205;V0401010206
A32: 2005 | B32: =AVERAGE(F32,H32,J32,L32,N32) -> 1518.3 | C32: 4 | E32: 1 | F32: =SegmentB!I32 -> 1101.25 | G32: 2 | H32: ='Segment C'!I33 -> 1341.1667 | I32: 3 | J32: =SegmentD!I34 -> 1578.3333 | K32: 4 | L32: =SegmentE!I78 -> 1695.75 | M32: 4 | N32: =SegmentF!I32 -> 1875 | O32: 4 | P32: V0101010101 | Q32: V0101010101 | R32: V0101010101 | S32: V0101010101 | T32: V0101010102 | U32: V0101010102 | V32: V0101010102 | W32: V0101010102 | X32: V0101010103 | Y32: V0101010103 | Z32: V0101010103 | AA32: V0101010103 | AB32: V0101010106;V0101010105;V0101010104 | AC32: V0101010106;V0101010105;V0101010104 | AD32: V0101010106;V0101010105;V0101010104 | AE32: V0101010106;V0101010105;V0101010104 | AQ32: V0401010000;V0401010101;V04010100102;V0401010103;V0401010104;V0401010105;V0401010106;V0401010201;V0401010202;V0401010203;V0401010204;V0401010205;V0401010206 | AR32: V0401010101 | AS32: V0401010102;V0401010103 | AT32: V0401010104 | AU32: V0401010104;V0401010105;V0401010106 | AV32: V0401010101 | AW32: V0401010102;V0401010103 | AX32: V0401010104 | AY32: V0401010104;V0401010105;V0401010106 | AZ32: V0401010101 | BA32: V0401010102;V0401010103 | BB32: V0401010104;V0401010204 | BC32: V0401010104;V0401010105;V0401010106;V0401010204;V0401010205;V0401010206
A33: 2006 | B33: =AVERAGE(F33,H33,J33,L33,N33) -> 1541.2 | C33: 4 | E33: 1 | F33: =SegmentB!I33 -> 1185.75 | G33: 2 | H33: ='Segment C'!I34 -> 1341.1667 | I33: 3 | J33: =SegmentD!I35 -> 1608.3333 | K33: 4 | L33: =SegmentE!I79 -> 1695.75 | M33: 4 | N33: =SegmentF!I33 -> 1875 | O33: 4 | P33: V0101010101 | Q33: V0101010101 | R33: V0101010101 | S33: V0101010101 | T33: V0101010102 | U33: V0101010102 | V33: V0101010102 | W33: V0101010102 | X33: V0101010103 | Y33: V0101010103 | Z33: V0101010103 | AA33: V0101010103 | AB33: V0101010106;V0101010105;V0101010104 | AC33: V0101010106;V0101010105;V0101010104 | AD33: V0101010106;V0101010105;V0101010104 | AE33: V0101010106;V0101010105;V0101010104 | AQ33: V0401010000;V0401010101;V04010100102;V0401010103;V0401010104;V0401010105;V0401010106;V0401010201;V0401010202;V0401010203;V0401010204;V0401010205;V0401010206 | AR33: V0401010101 | AS33: V0401010102;V0401010103 | AT33: V0401010104 | AU33: V0401010104;V0401010105;V0401010106 | AV33: V0401010101 | AW33: V0401010102;V0401010103 | AX33: V0401010104 | AY33: V0401010104;V0401010105;V0401010106 | AZ33: V0401010101 | BA33: V0401010102;V0401010103 | BB33: V0401010104;V0401010204 | BC33: V0401010104;V0401010105;V0401010106;V0401010204;V0401010205;V0401010206
A34: 2007 | B34: =AVERAGE(F34,H34,J34,L34,N34) -> 1551.5333 | C34: 4 | E34: 1 | F34: =SegmentB!I34 -> 1185.75 | G34: 2 | H34: ='Segment C'!I35 -> 1392.8333 | I34: 3 | J34: =SegmentD!I36 -> 1608.3333 | K34: 4 | L34: =SegmentE!I80 -> 1695.75 | M34: 4 | N34: =SegmentF!I34 -> 1875 | O34: 4 | P34: V0101010101 | Q34: V0101010101 | R34: V0101010101 | S34: V0101010101 | T34: V0101010102 | U34: V0101010102 | V34: V0101010102 | W34: V0101010102 | X34: V0101010103 | Y34: V0101010103 | Z34: V0101010103 | AA34: V0101010103 | AB34: V0101010106;V0101010105;V0101010104 | AC34: V0101010106;V0101010105;V0101010104 | AD34: V0101010106;V0101010105;V0101010104 | AE34: V0101010106;V0101010105;V0101010104 | AQ34: V0401010000;V0401010101;V04010100102;V0401010103;V0401010104;V0401010105;V0401010106;V0401010201;V0401010202;V0401010203;V0401010204;V0401010205;V0401010206 | AR34: V0401010101 | AS34: V0401010102;V0401010103 | AT34: V0401010104 | AU34: V0401010104;V0401010105;V0401010106 | AV34: V0401010101 | AW34: V0401010102;V0401010103 | AX34: V0401010104 | AY34: V0401010104;V0401010105;V0401010106 | AZ34: V0401010101 | BA34: V0401010102;V0401010103 | BB34: V0401010104;V0401010204 | BC34: V0401010104;V0401010105;V0401010106;V0401010204;V0401010205;V0401010206
A35: 2008 | B35: =AVERAGE(F35,H35,J35,L35,N35) -> 1601.6667 | C35: 4 | E35: 1 | F35: =SegmentB!I35 -> 1185.75 | G35: 2 | H35: ='Segment C'!I36 -> 1404 | I35: 3 | J35: =SegmentD!I37 -> 1608.3333 | K35: 4 | L35: =SegmentE!I81 -> 1695.75 | M35: 4 | N35: =SegmentF!I35 -> 2114.5 | O35: 4 | P35: V0101010101 | Q35: V0101010101 | R35: V0101010101 | S35: V0101010101 | T35: V0101010102 | U35: V0101010102 | V35: V0101010102 | W35: V0101010102 | X35: V0101010103 | Y35: V0101010103 | Z35: V0101010103 | AA35: V0101010103 | AB35: V0101010106;V0101010105;V0101010104 | AC35: V0101010106;V0101010105;V0101010104 | AD35: V0101010106;V0101010105;V0101010104 | AE35: V0101010106;V0101010105;V0101010104 | AQ35: V0401010000;V0401010101;V04010100102;V0401010103;V0401010104;V0401010105;V0401010106;V0401010201;V0401010202;V0401010203;V0401010204;V0401010205;V0401010206 | AR35: V0401010101 | AS35: V0401010102;V0401010103 | AT35: V0401010104 | AU35: V0401010104;V0401010105;V0401010106 | AV35: V0401010101 | AW35: V0401010102;V0401010103 | AX35: V0401010104 | AY35: V0401010104;V0401010105;V0401010106 | AZ35: V0401010101 | BA35: V0401010102;V0401010103 | BB35: V0401010104;V0401010204 | BC35: V0401010104;V0401010105;V0401010106;V0401010204;V0401010205;V0401010206
A36: 2009 | B36: =AVERAGE(F36,H36,J36,L36,N36) -> 1610.8667 | C36: 4 | E36: 1 | F36: =SegmentB!I36 -> 1231.75 | G36: 2 | H36: ='Segment C'!I37 -> 1404 | I36: 3 | J36: =SegmentD!I38 -> 1608.3333 | K36: 4 | L36: =SegmentE!I82 -> 1695.75 | M36: 4 | N36: =SegmentF!I36 -> 2114.5 | O36: 4 | P36: V0101010101 | Q36: V0101010101 | R36: V0101010101 | S36: V0101010101 | T36: V0101010102 | U36: V0101010102 | V36: V0101010102 | W36: V0101010102 | X36: V0101010103 | Y36: V0101010103 | Z36: V0101010103 | AA36: V0101010103 | AB36: V0101010106;V0101010105;V0101010104 | AC36: V0101010106;V0101010105;V0101010104 | AD36: V0101010106;V0101010105;V0101010104 | AE36: V0101010106;V0101010105;V0101010104 | AQ36: V0401010000;V0401010101;V04010100102;V0401010103;V0401010104;V0401010105;V0401010106;V0401010201;V0401010202;V0401010203;V0401010204;V0401010205;V0401010206 | AR36: V0401010101 | AS36: V0401010102;V0401010103 | AT36: V0401010104 | AU36: V0401010104;V0401010105;V0401010106 | AV36: V0401010101 | AW36: V0401010102;V0401010103 | AX36: V0401010104 | AY36: V0401010104;V0401010105;V0401010106 | AZ36: V0401010101 | BA36: V0401010102;V0401010103 | BB36: V0401010104;V0401010204 | BC36: V0401010104;V0401010105;V0401010106;V0401010204;V0401010205;V0401010206
A37: 2010 | B37: =AVERAGE(F37,H37,J37,L37,N37) -> 1622.5667 | C37: 4 | E37: 1 | F37: =SegmentB!I37 -> 1231.75 | G37: 2 | H37: ='Segment C'!I38 -> 1404 | I37: 3 | J37: =SegmentD!I39 -> 1628.8333 | K37: 4 | L37: =SegmentE!I83 -> 1733.75 | M37: 4 | N37: =SegmentF!I37 -> 2114.5 | O37: 4 | P37: V0101010101 | Q37: V0101010101 | R37: V0101010101 | S37: V0101010101 | T37: V0101010102 | U37: V0101010102 | V37: V0101010102 | W37: V0101010102 | X37: V0101010103 | Y37: V0101010103 | Z37: V0101010103 | AA37: V0101010103 | AB37: V0101010106;V0101010105;V0101010104 | AC37: V0101010106;V0101010105;V0101010104 | AD37: V0101010106;V0101010105;V0101010104 | AE37: V0101010106;V0101010105;V0101010104 | AG37: V0301030000;V0301030101;V0301030102;V0301030103;V0301030104;V0301030105;V0301030106;V0301030201;V0301030202;V0301030203;V0301030204;V0301030205;V0301030206 | AH37: V0301030101;V0301030201 | AI37: V0301030101;V0301030201 | AJ37: V0301030102;V0301030202 | AK37: V0301030102;V0301030103;V0301030104;V0301030105;V0301030106;V0301030202;V0301030203;V0301030204;V0301030205;V0301030206 | AL37: V0301030000;V0301030101;V0301030102;V0301030103;V0301030104;V0301030105;V0301030106;V0301030201;V0301030202;V0301030203;V0301030204;V0301030205;V0301030206 | AM37: V0301030101;V0301030201 | AN37: V0301030101;V0301030201 | AO37: V0301030102;V0301030202 | AP37: V0301030102;V0301030103;V0301030104;V0301030105;V0301030106;V0301030202;V0301030203;V0301030204;V0301030205;V0301030206 | AQ37: V0401010000;V0401010101;V04010100102;V0401010103;V0401010104;V0401010105;V0401010106;V0401010201;V0401010202;V0401010203;V0401010204;V0401010205;V0401010206 | AR37: V0401010101 | AS37: V0401010102;V0401010103 | AT37: V0401010104 | AU37: V0401010104;V0401010105;V0401010106 | AV37: V0401010101 | AW37: V0401010102;V0401010103 | AX37: V0401010104 | AY37: V0401010104;V0401010105;V0401010106 | AZ37: V0401010101;V0401010201 | BA37: V0401010102;V0401010103;V0401010202;V0401010203 | BB37: V0401010104;V0401010204 | BC37: V0401010104;V0401010105;V0401010106;V0401010204;V0401010205;V0401010206 | BD37: V0501030000;V0501030101;V05010300102;V0501010303;V0501030104;V0501030105;V0501030106;V0501030201;V0501030202;V0501030203;V0501030204;V0501030205;V0501030206 | BE37: V0501030101 | BF37: V0501030102;V0501030103 | BG37: V0501030104 | BH37: V0501030104;V0501030105;V0501030106 | BI37: V0501030101 | BJ37: V0501030102;V0501030103 | BK37: V0501030104 | BL37: V0501030104;V0501030105;V0501030106 | BM37: V0501030101;V0501030201 | BN37: V0501030102;V0501030103;V0501030202;V0501030203 | BO37: V0501030104;V0501030204 | BP37: V0501030104;V0501030105;V0501030106;V0501030204;V0501030205;V0501030206
A38: 2011 | B38: =AVERAGE(F38,H38,J38,L38,N38) -> 1622.5667 | C38: 4 | E38: 1 | F38: =SegmentB!I38 -> 1231.75 | G38: 2 | H38: ='Segment C'!I39 -> 1404 | I38: 3 | J38: =SegmentD!I40 -> 1628.8333 | K38: 4 | L38: =SegmentE!I84 -> 1733.75 | M38: 4 | N38: =SegmentF!I38 -> 2114.5 | O38: 4 | P38: V0101010101 | Q38: V0101010101 | R38: V0101010101 | S38: V0101010101 | T38: V0101010102 | U38: V0101010102 | V38: V0101010102 | W38: V0101010102 | X38: V0101010103 | Y38: V0101010103 | Z38: V0101010103 | AA38: V0101010103 | AB38: V0101010106;V0101010105;V0101010104 | AC38: V0101010106;V0101010105;V0101010104 | AD38: V0101010106;V0101010105;V0101010104 | AE38: V0101010106;V0101010105;V0101010104 | AG38: V0301030000;V0301030101;V0301030102;V0301030103;V0301030104;V0301030105;V0301030106;V0301030201;V0301030202;V0301030203;V0301030204;V0301030205;V0301030206 | AH38: V0301030101;V0301030201 | AI38: V0301030101;V0301030201 | AJ38: V0301030102;V0301030202 | AK38: V0301030102;V0301030103;V0301030104;V0301030105;V0301030106;V0301030202;V0301030203;V0301030204;V0301030205;V0301030206 | AL38: V0301030000;V0301030101;V0301030102;V0301030103;V0301030104;V0301030105;V0301030106;V0301030201;V0301030202;V0301030203;V0301030204;V0301030205;V0301030206 | AM38: V0301030101;V0301030201 | AN38: V0301030101;V0301030201 | AO38: V0301030102;V0301030202 | AP38: V0301030102;V0301030103;V0301030104;V0301030105;V0301030106;V0301030202;V0301030203;V0301030204;V0301030205;V0301030206 | AQ38: V0401010000;V0401010101;V04010100102;V0401010103;V0401010104;V0401010105;V0401010106;V0401010201;V0401010202;V0401010203;V0401010204;V0401010205;V0401010206 | AR38: V0401010101 | AS38: V0401010102;V0401010103 | AT38: V0401010104 | AU38: V0401010104;V0401010105;V0401010106 | AV38: V0401010101 | AW38: V0401010102;V0401010103 | AX38: V0401010104 | AY38: V0401010104;V0401010105;V0401010106 | AZ38: V0401010101;V0401010201 | BA38: V0401010102;V0401010103;V0401010202;V0401010203 | BB38: V0401010104;V0401010204 | BC38: V0401010104;V0401010105;V0401010106;V0401010204;V0401010205;V0401010206 | BD38: V0501030000;V0501030101;V05010300102;V0501010303;V0501030104;V0501030105;V0501030106;V0501030201;V0501030202;V0501030203;V0501030204;V0501030205;V0501030206 | BE38: V0501030101 | BF38: V0501030102;V0501030103 | BG38: V0501030104 | BH38: V0501030104;V0501030105;V0501030106 | BI38: V0501030101 | BJ38: V0501030102;V0501030103 | BK38: V0501030104 | BL38: V0501030104;V0501030105;V0501030106 | BM38: V0501030101;V0501030201 | BN38: V0501030102;V0501030103;V0501030202;V0501030203 | BO38: V0501030104;V0501030204 | BP38: V0501030104;V0501030105;V0501030106;V0501030204;V0501030205;V0501030206
A39: 2012 | B39: =AVERAGE(F39,H39,J39,L39,N39) -> 1605.2167 | C39: 4 | E39: 1 | F39: =SegmentB!I39 -> 1178 | G39: 2 | H39: ='Segment C'!I40 -> 1405.3333 | I39: 3 | J39: =SegmentD!I41 -> 1594.5 | K39: 4 | L39: =SegmentE!I85 -> 1733.75 | M39: 4 | N39: =SegmentF!I39 -> 2114.5 | O39: 4 | P39: V0101010101 | Q39: V0101010101 | R39: V0101010101 | S39: V0101010101 | T39: V0101010102 | U39: V0101010102 | V39: V0101010102 | W39: V0101010102 | X39: V0101010103 | Y39: V0101010103 | Z39: V0101010103 | AA39: V0101010103 | AB39: V0101010106;V0101010105;V0101010104 | AC39: V0101010106;V0101010105;V0101010104 | AD39: V0101010106;V0101010105;V0101010104 | AE39: V0101010106;V0101010105;V0101010104 | AG39: V0301030000;V0301030101;V0301030102;V0301030103;V0301030104;V0301030105;V0301030106;V0301030201;V0301030202;V0301030203;V0301030204;V0301030205;V0301030206 | AH39: V0301030101;V0301030201 | AI39: V0301030101;V0301030201 | AJ39: V0301030102;V0301030202 | AK39: V0301030102;V0301030103;V0301030104;V0301030105;V0301030106;V0301030202;V0301030203;V0301030204;V0301030205;V0301030206 | AL39: V0301030000;V0301030101;V0301030102;V0301030103;V0301030104;V0301030105;V0301030106;V0301030201;V0301030202;V0301030203;V0301030204;V0301030205;V0301030206 | AM39: V0301030101;V0301030201 | AN39: V0301030101;V0301030201 | AO39: V0301030102;V0301030202 | AP39: V0301030102;V0301030103;V0301030104;V0301030105;V0301030106;V0301030202;V0301030203;V0301030204;V0301030205;V0301030206 | AQ39: V0401010000;V0401010101;V04010100102;V0401010103;V0401010104;V0401010105;V0401010106;V0401010201;V0401010202;V0401010203;V0401010204;V0401010205;V0401010206 | AR39: V0401010101 | AS39: V0401010102;V0401010103 | AT39: V0401010104 | AU39: V0401010104;V0401010105;V0401010106 | AV39: V0401010101 | AW39: V0401010102;V0401010103 | AX39: V0401010104 | AY39: V0401010104;V0401010105;V0401010106 | AZ39: V0401010101;V0401010201 | BA39: V0401010102;V0401010103;V0401010202;V0401010203 | BB39: V0401010104;V0401010204 | BC39: V0401010104;V0401010105;V0401010106;V0401010204;V0401010205;V0401010206 | BD39: V0501030000;V0501030101;V05010300102;V0501010303;V0501030104;V0501030105;V0501030106;V0501030201;V0501030202;V0501030203;V0501030204;V0501030205;V0501030206 | BE39: V0501030101 | BF39: V0501030102;V0501030103 | BG39: V0501030104 | BH39: V0501030104;V0501030105;V0501030106 | BI39: V0501030101 | BJ39: V0501030102;V0501030103 | BK39: V0501030104 | BL39: V0501030104;V0501030105;V0501030106 | BM39: V0501030101;V0501030201 | BN39: V0501030102;V0501030103;V0501030202;V0501030203 | BO39: V0501030104;V0501030204 | BP39: V0501030104;V0501030105;V0501030106;V0501030204;V0501030205;V0501030206
